# 47장 에러 처리

🔖 오늘 읽은 범위 : 886 ~ 893p

---

## 47.2 try…catch…finally문

```jsx
// try...catch...finally 문으로 에러를 처리하면 프로그램이 강제 종료되지 않는다.
try {
  // 실행할 코드(에러가 발생할 가능성이 있는 코드)
} catch (err) {
  // try 코드 블록에서 에러가 발생하면 이 코드 블록의 코드가 실행된다.
  // err에는 try 코드 블록에서 발생한 Error 객체가 전달된다.
} finally {
  // 에러 발생과 상관없이 반드시 한 번 실행된다.
}
```

## 47.3 Error 객체

Error 생성자 함수는 에러 객체를 생성한다. 인수로 에러를 설명하는 메세지를 전달할 수 있다.

```jsx
const error = new Error("invalid");
```

Error 생성자 함수가 생성한 에러 객체는 message 프로퍼티와 stack 프로퍼티를 갖는다. message 프로퍼티의 값은 Error 생성자 함수에 인수로 전달한 에러 메세지이고, stack 프로퍼티의 값은 에러를 발생시킨 콜스택의 호출 정보를 나타내는 문자열이며 디버깅 목적으로 사용한다.

자바스크립트는 7가지의 에러 객체를 생성할 수 있는 Error 생성자 함수를 제공한다. 

| 생성자 함수 | 인스턴스 |
| --- | --- |
| Error | 일반적 에러 객체 |
| SyntaxError | 자바스크립트 문법에 맞지 않는 문법을 해석할 때 발생하는 에러 객체 |
| ReferenceError | 참조할 수 없는 Error 객체 전달 |
| TypeError | 피연산자 또는 인수의 데이터 타입이 유효하지 않을 때 발생하는 에러 객체 |
| RangeError | 숫자 값의 허용 범위를 벗어났을 때 발생하는 에러 객체 |
| URIError | encodeURI 또는 decodeURI 함수에 부적절한 인수를 전달했을 때 발생하는 에러 객체 |
| EvalError | eval 함수에서 발생하는 에러 객체 |

```jsx
1 @ 1;    // SyntaxError: Invalid or unexpected token
foo();    // ReferenceError: foo is not defined
null.foo; // TypeError: Cannot read property 'foo' of null
new Array(-1); // RangeError: Invalid array length
decodeURIComponent('%'); // URIError: URI malformed
```

## 47.4 throw문

- 에러 객체를 생성한다고 에러가 발생하는 것은 아니다. 에러를 발생시키려면 try 코드 블록에서 throw문으로 에러 객체를 던져야 한다.
- throw문의 표현식은 어떤 값이라도 상관없지만 일반적으로 에러 객체를 지정한다.
- 에러를 던지면 catch문의 에러 변수가 생성되고 던져진 에러 객체가 할당된다. 그리고 catch 코드 블록이 실행되기 시작한다.

```jsx
// 외부에서 전달받은 콜백 함수를 n번만큼 반복 호출한다
const repeat = (n, f) => {
  // 매개변수 f에 전달된 인수가 함수가 아니면 TypeError를 발생시킨다.
  if (typeof f !== 'function') throw new TypeError('f must be a function');

  for (var i = 0; i < n; i++) {
    f(i); // i를 전달하면서 f를 호출
  }
};

try {
  repeat(2, 1); // 두 번째 인수가 함수가 아니므로 TypeError가 발생(throw)한다.
} catch (err) {
  console.error(err); // TypeError: f must be a function
}
```

## 47.5 에러의 전파

에러는 호출자 방향, 즉 콜 스택 아래 방향(실행 중인 실행 컨텍스트가 푸시되기 직전에 푸시된 실행 컨텍스트 방향)으로 전파된다.

```jsx
const foo = () => {
  throw Error('foo에서 발생한 에러'); // ④
};

const bar = () => {
  foo(); // ③
};

const baz = () => {
  bar(); // ②
};

try {
  baz(); // ①
} catch (err) {
  console.error(err);
}
```

(1)에서 baz 함수를 호출하면 (2)에서 bar 함수가 호출되고 (3)에서 foo 함수가 호출되고 foo 함수는 (4)에서 에러를 throw한다. 이 때 foo 함수가 throw한 에러는 다음과 같이 호출자에게 전파되어 전역에서 캐치된다.

이처럼 throw된 에러를 캐치하지 않으면 호출자 방향으로 전파된다. 이때 throw된 에러를 캐치하여 적절히 대응하면 프로그램을 강제 종료시키지 않고 코드의 실행 흐름을 복구할 수 있다.

**주의할 것은 비동기 함수인 setTimeout이나 프로미스 후속 처리 메서드의 콜백 함수는 호출자가 없다는 것이다.** setTimeout이나 프로미스 후속 처리 메서드의 콜백 함수는 태스크 큐나 마이크로태스크 큐에 일시 저장되었다가 콜 스택이 비면 이벤트 루프에 의해 콜 스택으로 푸시되어 실행된다. 이때 콜 스택에 푸시된 콜백 함수의 실행 컨텍스트는 콜 스택의 가장 하부에 존재하게 된다. 따라서 에러를 전파할 호출자가 존재하지 않는다.
